<?xml version="1.0" ?>
<robot name="texbot" xmlns:xacro="http://www.ros.org/wiki/xacro">
  <!-- Wheels -->
  <!-- in kg-->
  <!-- Defining the colors used in this robot -->
  <material name="Black">
    <color rgba="0.0 0.0 0.0 1.0"/>
  </material>
  <material name="Red">
    <color rgba="0.8 0.0 0.0 1.0"/>
  </material>
  <material name="White">
    <color rgba="1.0 1.0 1.0 1.0"/>
  </material>
  <material name="Blue">
    <color rgba="0.0 0.0 0.8 1.0"/>
  </material>
  <!-- PROPERTY LIST -->
  <!--All units in m-kg-s-radians unit system -->
  <!-- Main body radius and height -->
  <!-- Main Body Cylinder base   -->
  <!-- in kg-->
  <!-- caster wheel radius and height -->
  <!-- caster wheel mass -->
  <!-- in kg-->
  <!-- caster wheel radius and height -->
  <!-- caster wheel mass -->
  <!-- in kg-->
  <!-- Wheels -->
   --&gt; 
  <!-- in kg-->
  <!-- Hokuyo Laser scanner -->
  <!-- Macro for calculating inertia of cylinder -->
  <!-- BASE-FOOTPRINT -->
  <!-- base_footprint is a fictitious link(frame) that is on the ground right below base_link origin -->
  <link name="base_footprint">
    <inertial>
      <mass value="0.0001"/>
      <origin xyz="0 0 0"/>
      <inertia ixx="0.0001" ixy="0.0" ixz="0.0" iyy="0.0001" iyz="0.0" izz="0.0001"/>
    </inertial>
    <visual>
      <origin rpy="0 0 0" xyz="0 0 0"/>
      <geometry>
        <box size="0.001 0.001 0.001"/>
      </geometry>
    </visual>
  </link>
  <gazebo reference="base_footprint">
    <turnGravityOff>false</turnGravityOff>
  </gazebo>
  <joint name="base_footprint_joint" type="fixed">
    <origin rpy="0 0 0" xyz="0 0 0.04"/>
    <parent link="base_footprint"/>
    <child link="base_link"/>
  </joint>
  <!-- BASE-LINK -->
  <!--Actual body/chassis of the robot-->
  <link name="base_link">
    <inertial>
      <mass value="5"/>
      <origin xyz="0 0 0"/>
      <!--The 3x3 rotational inertia matrix. -->
      <inertia ixx="0.0282916666667" ixy="0" ixz="0" iyy="0.0282916666667" iyz="0" izz="0.05625"/>
    </inertial>
    <visual>
      <origin rpy="0 0 0" xyz="0 0 0"/>
      <geometry>
        <cylinder length="0.02" radius="0.15"/>
      </geometry>
      <material name="White"/>
    </visual>
    <collision>
      <origin rpy="0 0 0 " xyz="0 0 0"/>
      <geometry>
        <cylinder length="0.02" radius="0.15"/>
      </geometry>
    </collision>
  </link>
  <gazebo reference="base_link">
    <material>Gazebo/White</material>
    <turnGravityOff>false</turnGravityOff>
  </gazebo>
  <!--fb : front, back ; lr: left, right -->
  <link name="front_right_wheel">
    <visual>
      <origin rpy="1.57079632679 0  0 " xyz="0 0 0"/>
      <geometry>
        <cylinder length="0.02" radius="0.04"/>
      </geometry>
      <material name="DarkGray"/>
    </visual>
    <collision>
      <origin rpy="1.57079632679 0 0 " xyz="0 0 0"/>
      <geometry>
        <cylinder length="0.02" radius="0.04"/>
      </geometry>
    </collision>
    <inertial>
      <mass value="2.5"/>
      <origin xyz="0 0 0"/>
      <inertia ixx="0.00108333333333" ixy="0" ixz="0" iyy="0.00108333333333" iyz="0" izz="0.002"/>
    </inertial>
  </link>
  <gazebo reference="front_right_wheel">
    <mu1 value="1.0"/>
    <mu2 value="1.0"/>
    <kp value="10000000.0"/>
    <kd value="1.0"/>
    <fdir1 value="1 0 0"/>
    <material>Gazebo/Grey</material>
    <turnGravityOff>false</turnGravityOff>
  </gazebo>
  <joint name="front_right_wheel_joint" type="continuous">
    <parent link="base_link"/>
    <child link="front_right_wheel"/>
    <origin rpy="0 0 0" xyz="0.0 0.15 0.0"/>
    <axis rpy="0  0" xyz="0 1 0"/>
    <limit effort="100" velocity="100"/>
    <joint_properties damping="0.0" friction="0.0"/>
  </joint>
  <!-- Transmission is important to link the joints and the controller -->
  <transmission name="front_right_wheel_joint_trans">
    <type>transmission_interface/SimpleTransmission</type>
    <joint name="front_right_wheel_joint"/>
    <actuator name="front_right_wheel_joint_motor">
      <hardwareInterface>EffortJointInterface</hardwareInterface>
      <mechanicalReduction>1</mechanicalReduction>
    </actuator>
  </transmission>
  <!--fb : front, back ; lr: left, right -->
  <link name="front_left_wheel">
    <visual>
      <origin rpy="1.57079632679 0  0 " xyz="0 0 0"/>
      <geometry>
        <cylinder length="0.02" radius="0.04"/>
      </geometry>
      <material name="DarkGray"/>
    </visual>
    <collision>
      <origin rpy="1.57079632679 0 0 " xyz="0 0 0"/>
      <geometry>
        <cylinder length="0.02" radius="0.04"/>
      </geometry>
    </collision>
    <inertial>
      <mass value="2.5"/>
      <origin xyz="0 0 0"/>
      <inertia ixx="0.00108333333333" ixy="0" ixz="0" iyy="0.00108333333333" iyz="0" izz="0.002"/>
    </inertial>
  </link>
  <gazebo reference="front_left_wheel">
    <mu1 value="1.0"/>
    <mu2 value="1.0"/>
    <kp value="10000000.0"/>
    <kd value="1.0"/>
    <fdir1 value="1 0 0"/>
    <material>Gazebo/Grey</material>
    <turnGravityOff>false</turnGravityOff>
  </gazebo>
  <joint name="front_left_wheel_joint" type="continuous">
    <parent link="base_link"/>
    <child link="front_left_wheel"/>
    <origin rpy="0 0 0" xyz="0.0 -0.15 0.0"/>
    <axis rpy="0  0" xyz="0 1 0"/>
    <limit effort="100" velocity="100"/>
    <joint_properties damping="0.0" friction="0.0"/>
  </joint>
  <!-- Transmission is important to link the joints and the controller -->
  <transmission name="front_left_wheel_joint_trans">
    <type>transmission_interface/SimpleTransmission</type>
    <joint name="front_left_wheel_joint"/>
    <actuator name="front_left_wheel_joint_motor">
      <hardwareInterface>EffortJointInterface</hardwareInterface>
      <mechanicalReduction>1</mechanicalReduction>
    </actuator>
  </transmission>
  <!--Caster front  -->
  <!--
  <link name="caster_front_link">
    <visual>
      <origin rpy="1.57079632679 0 0" xyz="0 0.02 0"/>
      <geometry>
        <sphere radius="0.025"/>
      </geometry>
      <material name="Blue"/>
    </visual>
    <collision>
      <geometry>
        <sphere radius="0.025"/>
      </geometry>
      <origin rpy="1.57079632679 0 0" xyz="0 0.02 0"/>
    </collision>
    <inertial>
      <mass value="0.5"/>
      <origin xyz="0 0 0"/>
      <inertia ixx="0.001" ixy="0.0" ixz="0.0" iyy="0.001" iyz="0.0" izz="0.001"/>
    </inertial>
  </link>
  <joint name="caster_front_joint" type="fixed">
    <parent link="base_link"/>
    <child link="caster_front_link"/>
    <origin rpy="-1.57079632679 0 0" xyz="0.115 0.0 0.007"/>
  </joint>
  <gazebo reference="caster_front_link">
    <turnGravityOff>false</turnGravityOff>
  </gazebo>
  -->
  
  <!--Caster back  -->
  <link name="caster_back_link">
    <visual>
      <origin rpy="1.57079632679 0 0" xyz="0.02 0.02 0 "/>
      <geometry>
        <sphere radius="0.025"/>
      </geometry>
      <material name="Red"/>
    </visual>
    <collision>
      <geometry>
        <sphere radius="0.025"/>
      </geometry>
      <origin rpy="1.57079632679 0 0" xyz="0 0.02 0 "/>
    </collision>
    <inertial>
      <mass value="0.9"/>
      <origin xyz="0 0 0"/>
      <inertia ixx="0.001" ixy="0.0" ixz="0.0" iyy="0.001" iyz="0.0" izz="0.001"/>
    </inertial>
  </link>
  <joint name="caster_back_joint" type="fixed">
    <parent link="base_link"/>
    <child link="caster_back_link"/>
    <origin rpy="-1.57079632679 0 0" xyz="-0.135 0.0 0.009"/>
  </joint>
  <gazebo reference="caster_back_link">
    <turnGravityOff>false</turnGravityOff>
  </gazebo>

  <!-- SENSORS -->
  <!-- hokuyo -->
  <link name="hokuyo_link">
    <visual>
      <origin rpy="0 0 0.785398" xyz="-0.025 -0.06 0"/>
      <geometry>
        <box size="0.03 0.03 0.03"/>
      </geometry>
      <material name="Blue"/>
    </visual>
  </link>
  <joint name="hokuyo_joint" type="fixed">
    <origin rpy="0 0 0" xyz="0.125 0 0.02"/>
    <parent link="base_link"/>
    <child link="hokuyo_link"/>
  </joint>
  <gazebo reference="hokuyo_link">
    <material>Gazebo/Blue</material>
    <turnGravityOff>false</turnGravityOff>
    <sensor name="head_hokuyo_sensor" type="ray">
      <pose>0.025 0 0 0 0 0</pose>
      <visualize>false</visualize>
      <update_rate>40</update_rate>
      <ray>
        <scan>
          <horizontal>
            <samples>720</samples>
            <resolution>1</resolution>
            <min_angle>-0.785398</min_angle>
            <max_angle>0.785398</max_angle>
          </horizontal>
        </scan>
        <range>
          <min>0.10</min>
          <max>10.0</max>
          <resolution>0.001</resolution>
        </range>
      </ray>
      <plugin filename="libgazebo_ros_laser.so" name="gazebo_ros_head_hokuyo_controller">
        <topicName>/scan</topicName>
        <frameName>hokuyo_link</frameName>
      </plugin>
    </sensor>
  </gazebo>
  <link name="obstacle_detector_2">
    <visual>
      <origin rpy="0 0 0.785398" xyz="0.1 0.06 0"/>
      <geometry>
        <box size="0.03 0.03 0.03"/>
      </geometry>
      <material name="Blue"/>
    </visual>
  </link>
  <joint name="obstacle_detector_2" type="fixed">
    <parent link="base_link"/>
    <child link="obstacle_detector_2"/>
    <origin rpy="0 0 0" xyz="0 0 0.02"/>
  </joint>
  <gazebo reference="obstacle_detector_2">
    <material>Gazebo/Blue</material>
    <turnGravityOff>false</turnGravityOff>
  </gazebo>

  <!-- Camera 1-->
  <link name="camera_1_link">
    <collision>
      <origin xyz="0 0 0" rpy="0 0 0"/>
      <geometry>
    <box size="0.005 0.05 0.02"/>
      </geometry>
    </collision>
    <visual>
      <origin xyz="0 0 0" rpy="0 0 0"/>
      <geometry>
    <box size="0.005 0.05 0.02"/>
      </geometry>
      <material name="red"/>
    </visual>
    <inertial>
      <mass value="0.001" />
      <origin xyz="0 0 0" rpy="0 0 0"/>
      <inertia ixx="1e-6" ixy="0" ixz="0" iyy="1e-6" iyz="0" izz="1e-6" />
    </inertial>
  </link>
  <joint name="camera_1_joint" type="fixed">
    <axis xyz="0 1 0" />
    <origin xyz="0.135 0.0 -0.031" rpy="0 1.57079632679 0"/>
    <parent link="camera_bar_1_link"/>
    <child link="camera_1_link"/>
  </joint>
  <gazebo reference="camera_1_link">
    <sensor type="camera" name="camera1">
      <update_rate>30.0</update_rate>
      <camera name="head">
        <horizontal_fov>2.9</horizontal_fov>
        <image>
          <width>800</width>
          <height>800</height>
          <format>R8G8B8</format>
        </image>
        <clip>
          <near>0.001</near>
          <far>300</far>
        </clip>
        <noise>
          <type>gaussian</type>
          <mean>0.0</mean>
          <stddev>0.007</stddev>
        </noise>
      </camera>
      <plugin name="camera_controller" filename="libgazebo_ros_camera.so">
        <alwaysOn>true</alwaysOn>
        <updateRate>0.0</updateRate>
        <cameraName>/texbot/camera1</cameraName>
        <imageTopicName>image_raw</imageTopicName>
        <cameraInfoTopicName>camera_info</cameraInfoTopicName>
        <frameName>camera_1_link</frameName>
        <hackBaseline>0.07</hackBaseline>
        <distortionK1>0.0</distortionK1>
        <distortionK2>0.0</distortionK2>
        <distortionK3>0.0</distortionK3>
        <distortionT1>0.0</distortionT1>
        <distortionT2>0.0</distortionT2>
      </plugin>
    </sensor>
  </gazebo>
  <link name="camera_bar_1_link">
    <visual>
      <origin rpy="0 0 0" xyz="0.135 0.02 -0.0225"/>
      <geometry>
        <box size="0.01 0.01 0.02"/>
      </geometry>
    </visual>
  </link>
  <joint name="camera_bar_1_joint" type="fixed">
    <parent link="base_link"/>
    <child link="camera_bar_1_link"/>
    <origin rpy="0 0 0" xyz="0 0 0"/>
  </joint>
  <gazebo reference="camera_bar_1_link">
    <turnGravityOff>false</turnGravityOff>
  </gazebo>
  <link name="camera_bar_2_link">
    <visual>
      <origin rpy="0 0 0" xyz="0.135 -0.02 -0.0225"/>
      <geometry>
        <box size="0.01 0.01 0.02"/>
      </geometry>
    </visual>
  </link>
  <joint name="camera_bar_2_joint" type="fixed">
    <parent link="base_link"/>
    <child link="camera_bar_2_link"/>
    <origin rpy="0 0 0" xyz="0 0 0"/>
  </joint>
  <gazebo reference="camera_bar_2_link">
    <turnGravityOff>false</turnGravityOff>
  </gazebo>

<!--LED Plugin-->
  <gazebo>
    <link name='led_1_link'>
      <pose>0.04 -0.03 0.05 0 0 0</pose>
      <light name='lamp' type='spot'>
        <pose>0 0 0.0 0 3.14159 0</pose>
        <attenuation>
          <range>30</range>
          <linear>0.05</linear>
        </attenuation>
        <diffuse>0.5 1 1 1</diffuse>
        <specular>1 1 1 1</specular>
        <spot>
          <inner_angle>0.3</inner_angle>
          <outer_angle>0.35</outer_angle>
          <falloff>1</falloff>
        </spot>
        <direction>0 0 -1</direction>
      </light>
      <visual name='lamp'>
        <geometry>
          <sphere>
            <radius>0.015</radius>
          </sphere>
        </geometry>
        <transparency>0.3</transparency>
        <material>
          <ambient>0.2 0.9 0.1 1</ambient>
          <diffuse>0.2 0.9 0.1 1</diffuse>
          <specular>0.2 0.9 0.1 1</specular>
          <emissive>0.2 0.9 0.1 1</emissive>
        </material>
      </visual>
    </link>
    <joint name='led_1_joint' type='fixed'>
      <parent>base_link</parent>
      <child>led_1_link</child>
      </joint>
    <plugin name='light_control' filename='libLedRosControl.so'>
      <enable>true</enable>
      <light>
        <id>led_1_link/lamp</id>
        <duration>0.5</duration>
        <interval>0.5</interval>
        <enable>true</enable>
      </light>
    </plugin>
  </gazebo>

  <gazebo>
    <link name='led_2_link'>
      <pose>0.04 0.03 0.05 0 0 0</pose>
      <light name='lamp' type='spot'>
        <pose>0 0 0.0 0 3.14159 0</pose>
        <attenuation>
          <range>30</range>
          <linear>0.05</linear>
        </attenuation>
        <diffuse>0.5 1 1 1</diffuse>
        <specular>1 1 1 1</specular>
        <spot>
          <inner_angle>0.3</inner_angle>
          <outer_angle>0.35</outer_angle>
          <falloff>1</falloff>
        </spot>
        <direction>0 0 -1</direction>
      </light>
      <visual name='lamp'>
        <geometry>
          <sphere>
            <radius>0.015</radius>
          </sphere>
        </geometry>
        <transparency>0.3</transparency>
        <material>
          <ambient>0.2 0.9 0.1 1</ambient>
          <diffuse>0.2 0.9 0.1 1</diffuse>
          <specular>0.2 0.9 0.1 1</specular>
          <emissive>0.2 0.9 0.1 1</emissive>
        </material>
      </visual>
    </link>
    <joint name='led_2_joint' type='fixed'>
      <parent>base_link</parent>
      <child>led_2_link</child>
      </joint>
    <plugin name='light_control' filename='libLedRosControl.so'>
      <enable>true</enable>
      <light>
        <id>led_2_link/lamp</id>
        <duration>0.5</duration>
        <interval>0.5</interval>
        <enable>true</enable>
      </light>
    </plugin>
  </gazebo>
    

<!-- Differential drive controller  -->
  <gazebo>
    <plugin filename="libgazebo_ros_diff_drive.so" name="differential_drive_controller_front">
      <rosDebugLevel>Debug</rosDebugLevel>
      <publishWheelTF>True</publishWheelTF>
      <publishTf>1</publishTf>
      <publishWheelJointState>true</publishWheelJointState>
      <alwaysOn>true</alwaysOn>
      <updateRate>100.0</updateRate>
      <leftJoint>front_left_wheel_joint</leftJoint>
      <rightJoint>front_right_wheel_joint</rightJoint>
      <wheelSeparation>0.3</wheelSeparation>
      <wheelDiameter>0.08</wheelDiameter>
      <broadcastTF>1</broadcastTF>
      <wheelTorque>30</wheelTorque>
      <wheelAcceleration>1.2</wheelAcceleration>
      <commandTopic>cmd_vel</commandTopic>
      <odometryFrame>odom</odometryFrame>
      <odometryTopic>odom</odometryTopic>
      <robotBaseFrame>base_link</robotBaseFrame>
      <legacyMode>True</legacyMode>
    </plugin>
  </gazebo>
  <!--
	  <gazebo>
	    <plugin name="kobuki_controller" filename="libgazebo_ros_kobuki.so">
	      <publish_tf>1</publish_tf>
	      <left_wheel_joint_name>front_left_wheel_joint</left_wheel_joint_name>
	      <right_wheel_joint_name>front_right_wheel_joint</right_wheel_joint_name>
	      <wheel_separation>.30</wheel_separation>
	      <wheel_diameter>0.08</wheel_diameter>
	      <torque>30.0</torque>
	      <velocity_command_timeout>0.6</velocity_command_timeout>
	    </plugin>
	  </gazebo>
-->
</robot>
